WARNING  urllib3.connectionpool:connectionpool.py:780 Retrying (Retry(total=2, connect=None, read=None, redirect=None, status=None)) after connection broken by 'NewConnectionError('<urllib3.connection.HTTPConnection object at 0x1034c05b0>: Failed to establish a new connection: [Errno 61] Connection refused')': /session/cd0c0e06b7d1d9b4d23e4cde5b1115ae
WARNING  urllib3.connectionpool:connectionpool.py:780 Retrying (Retry(total=1, connect=None, read=None, redirect=None, status=None)) after connection broken by 'NewConnectionError('<urllib3.connection.HTTPConnection object at 0x103531b50>: Failed to establish a new connection: [Errno 61] Connection refused')': /session/cd0c0e06b7d1d9b4d23e4cde5b1115ae
WARNING  urllib3.connectionpool:connectionpool.py:780 Retrying (Retry(total=0, connect=None, read=None, redirect=None, status=None)) after connection broken by 'NewConnectionError('<urllib3.connection.HTTPConnection object at 0x10352b640>: Failed to establish a new connection: [Errno 61] Connection refused')': /session/cd0c0e06b7d1d9b4d23e4cde5b1115ae
INFO     common.loging_handler:base_case_test.py:29 =====>部门管理:执行测试结束<=====